2020-09-22 16:47:13,144 INFO: Microblog startup [in D:\DeveloperPlanet\Projects\python\flask-form\app\__init__.py:81]
2020-09-22 16:47:13,151 INFO: Microblog startup [in D:\DeveloperPlanet\Projects\python\flask-form\app\__init__.py:81]
2020-09-22 16:47:13,151 INFO: Microblog startup [in D:\DeveloperPlanet\Projects\python\flask-form\app\__init__.py:81]
2020-09-22 18:32:02,186 INFO: Microblog startup [in D:\DeveloperPlanet\Projects\python\flask-form\app\__init__.py:81]
2020-09-22 18:32:11,515 INFO: Microblog startup [in D:\DeveloperPlanet\Projects\python\flask-form\app\__init__.py:81]
2020-09-22 18:32:25,057 INFO: Microblog startup [in D:\DeveloperPlanet\Projects\python\flask-form\app\__init__.py:81]
2020-09-22 18:32:38,588 INFO: Microblog startup [in D:\DeveloperPlanet\Projects\python\flask-form\app\__init__.py:81]
2020-09-22 18:41:21,435 INFO: Microblog startup [in D:\DeveloperPlanet\Projects\python\flask-form\app\__init__.py:81]
2020-09-22 18:42:44,533 INFO: Microblog startup [in D:\DeveloperPlanet\Projects\python\flask-form\app\__init__.py:81]
2020-09-22 18:42:44,636 ERROR: Exception on / [GET] [in d:\developerplanet\projects\python\flask-form\flaskenv\lib\site-packages\flask\app.py:1892]
Traceback (most recent call last):
  File "d:\developerplanet\projects\python\flask-form\flaskenv\lib\site-packages\flask\app.py", line 2447, in wsgi_app
    response = self.full_dispatch_request()
  File "d:\developerplanet\projects\python\flask-form\flaskenv\lib\site-packages\flask\app.py", line 1952, in full_dispatch_request
    rv = self.handle_user_exception(e)
  File "d:\developerplanet\projects\python\flask-form\flaskenv\lib\site-packages\flask\app.py", line 1821, in handle_user_exception
    reraise(exc_type, exc_value, tb)
  File "d:\developerplanet\projects\python\flask-form\flaskenv\lib\site-packages\flask\_compat.py", line 39, in reraise
    raise value
  File "d:\developerplanet\projects\python\flask-form\flaskenv\lib\site-packages\flask\app.py", line 1950, in full_dispatch_request
    rv = self.dispatch_request()
  File "d:\developerplanet\projects\python\flask-form\flaskenv\lib\site-packages\flask\app.py", line 1936, in dispatch_request
    return self.view_functions[rule.endpoint](**req.view_args)
  File "d:\developerplanet\projects\python\flask-form\flaskenv\lib\site-packages\flask_login\utils.py", line 270, in decorated_view
    elif not current_user.is_authenticated:
  File "d:\developerplanet\projects\python\flask-form\flaskenv\lib\site-packages\werkzeug\local.py", line 347, in __getattr__
    return getattr(self._get_current_object(), name)
  File "d:\developerplanet\projects\python\flask-form\flaskenv\lib\site-packages\werkzeug\local.py", line 306, in _get_current_object
    return self.__local()
  File "d:\developerplanet\projects\python\flask-form\flaskenv\lib\site-packages\flask_login\utils.py", line 26, in <lambda>
    current_user = LocalProxy(lambda: _get_user())
  File "d:\developerplanet\projects\python\flask-form\flaskenv\lib\site-packages\flask_login\utils.py", line 346, in _get_user
    current_app.login_manager._load_user()
  File "d:\developerplanet\projects\python\flask-form\flaskenv\lib\site-packages\werkzeug\local.py", line 347, in __getattr__
    return getattr(self._get_current_object(), name)
AttributeError: 'Flask' object has no attribute 'login_manager'
2020-09-22 18:43:21,604 ERROR: Exception on / [GET] [in d:\developerplanet\projects\python\flask-form\flaskenv\lib\site-packages\flask\app.py:1892]
Traceback (most recent call last):
  File "d:\developerplanet\projects\python\flask-form\flaskenv\lib\site-packages\flask\app.py", line 2447, in wsgi_app
    response = self.full_dispatch_request()
  File "d:\developerplanet\projects\python\flask-form\flaskenv\lib\site-packages\flask\app.py", line 1952, in full_dispatch_request
    rv = self.handle_user_exception(e)
  File "d:\developerplanet\projects\python\flask-form\flaskenv\lib\site-packages\flask\app.py", line 1821, in handle_user_exception
    reraise(exc_type, exc_value, tb)
  File "d:\developerplanet\projects\python\flask-form\flaskenv\lib\site-packages\flask\_compat.py", line 39, in reraise
    raise value
  File "d:\developerplanet\projects\python\flask-form\flaskenv\lib\site-packages\flask\app.py", line 1950, in full_dispatch_request
    rv = self.dispatch_request()
  File "d:\developerplanet\projects\python\flask-form\flaskenv\lib\site-packages\flask\app.py", line 1936, in dispatch_request
    return self.view_functions[rule.endpoint](**req.view_args)
  File "d:\developerplanet\projects\python\flask-form\flaskenv\lib\site-packages\flask_login\utils.py", line 270, in decorated_view
    elif not current_user.is_authenticated:
  File "d:\developerplanet\projects\python\flask-form\flaskenv\lib\site-packages\werkzeug\local.py", line 347, in __getattr__
    return getattr(self._get_current_object(), name)
  File "d:\developerplanet\projects\python\flask-form\flaskenv\lib\site-packages\werkzeug\local.py", line 306, in _get_current_object
    return self.__local()
  File "d:\developerplanet\projects\python\flask-form\flaskenv\lib\site-packages\flask_login\utils.py", line 26, in <lambda>
    current_user = LocalProxy(lambda: _get_user())
  File "d:\developerplanet\projects\python\flask-form\flaskenv\lib\site-packages\flask_login\utils.py", line 346, in _get_user
    current_app.login_manager._load_user()
  File "d:\developerplanet\projects\python\flask-form\flaskenv\lib\site-packages\werkzeug\local.py", line 347, in __getattr__
    return getattr(self._get_current_object(), name)
AttributeError: 'Flask' object has no attribute 'login_manager'
2020-09-22 18:46:51,722 INFO: Microblog startup [in D:\DeveloperPlanet\Projects\python\flask-form\app\__init__.py:81]
2020-09-22 18:46:59,166 ERROR: Exception on / [GET] [in d:\developerplanet\projects\python\flask-form\flaskenv\lib\site-packages\flask\app.py:1892]
Traceback (most recent call last):
  File "d:\developerplanet\projects\python\flask-form\flaskenv\lib\site-packages\flask\app.py", line 2447, in wsgi_app
    response = self.full_dispatch_request()
  File "d:\developerplanet\projects\python\flask-form\flaskenv\lib\site-packages\flask\app.py", line 1952, in full_dispatch_request
    rv = self.handle_user_exception(e)
  File "d:\developerplanet\projects\python\flask-form\flaskenv\lib\site-packages\flask\app.py", line 1821, in handle_user_exception
    reraise(exc_type, exc_value, tb)
  File "d:\developerplanet\projects\python\flask-form\flaskenv\lib\site-packages\flask\_compat.py", line 39, in reraise
    raise value
  File "d:\developerplanet\projects\python\flask-form\flaskenv\lib\site-packages\flask\app.py", line 1950, in full_dispatch_request
    rv = self.dispatch_request()
  File "d:\developerplanet\projects\python\flask-form\flaskenv\lib\site-packages\flask\app.py", line 1936, in dispatch_request
    return self.view_functions[rule.endpoint](**req.view_args)
  File "d:\developerplanet\projects\python\flask-form\flaskenv\lib\site-packages\flask_login\utils.py", line 270, in decorated_view
    elif not current_user.is_authenticated:
  File "d:\developerplanet\projects\python\flask-form\flaskenv\lib\site-packages\werkzeug\local.py", line 347, in __getattr__
    return getattr(self._get_current_object(), name)
  File "d:\developerplanet\projects\python\flask-form\flaskenv\lib\site-packages\werkzeug\local.py", line 306, in _get_current_object
    return self.__local()
  File "d:\developerplanet\projects\python\flask-form\flaskenv\lib\site-packages\flask_login\utils.py", line 26, in <lambda>
    current_user = LocalProxy(lambda: _get_user())
  File "d:\developerplanet\projects\python\flask-form\flaskenv\lib\site-packages\flask_login\utils.py", line 346, in _get_user
    current_app.login_manager._load_user()
  File "d:\developerplanet\projects\python\flask-form\flaskenv\lib\site-packages\werkzeug\local.py", line 347, in __getattr__
    return getattr(self._get_current_object(), name)
AttributeError: 'Flask' object has no attribute 'login_manager'
